<?xml version="1.0"?>
<robot xmlns:xacro="http://www.ros.org/wiki/xacro" name="simple_robot">

  <!-- Define Parameters -->
  <xacro:property name="foot_to_camera_base" value="0.16"/>
  <xacro:property name="camera_stalk_height" value="0.04"/>
  <xacro:property name="joint_limit_lower" value="-3.14"/>
  <xacro:property name="joint_limit_upper" value="3.14"/>
  <xacro:property name="joint_effort" value="10"/>
  <xacro:property name="joint_velocity" value="1"/>
  <xacro:property name="baseline" value="0.1625"/>

  <!-- Links -->
  <link name="base_link"/>
  <link name="h_rod"/>
  <link name="cam_left">
    <visual>
      <geometry>
        <box size="0.05 0.05 0.05"/>
      </geometry>
      <material name="green">
        <color rgba="0 1 0 1"/>
      </material>
    </visual>
  </link>
  <link name="cam_right">
    <visual>
      <geometry>
        <box size="0.05 0.05 0.05"/>
      </geometry>
      <material name="blue">
        <color rgba="0 0 1 1"/>
      </material>
    </visual>
  </link>

  <!-- Joints -->
  <joint name="pitch_inclination" type="revolute">
    <parent link="base_link"/>
    <child link="h_rod"/>
    <origin xyz="0 0 ${foot_to_camera_base}" rpy="0 0 0"/>
    <axis xyz="1 0 0"/>
    <limit lower="${joint_limit_lower}" upper="${joint_limit_upper}" effort="${joint_effort}" velocity="${joint_velocity}"/>
  </joint>

  <joint name="cam_left_yaw" type="revolute">
    <parent link="h_rod"/>
    <child link="cam_left"/>
    <origin xyz="-${baseline/2} 0 ${camera_stalk_height}" rpy="0 0 0"/>
    <axis xyz="0 0 1"/>
    <limit lower="${joint_limit_lower}" upper="${joint_limit_upper}" effort="${joint_effort}" velocity="${joint_velocity}"/>
  </joint>

  <joint name="cam_right_yaw" type="revolute">
    <parent link="h_rod"/>
    <child link="cam_right"/>
    <origin xyz="${baseline/2} 0 ${camera_stalk_height}" rpy="0 0 0"/>
    <axis xyz="0 0 1"/>
    <limit lower="${joint_limit_lower}" upper="${joint_limit_upper}" effort="${joint_effort}" velocity="${joint_velocity}"/>
  </joint>

</robot>
