<?xml version="1.0" ?>
<!-- =================================================================================== -->
<!-- |    This document was autogenerated by xacro from camera.xacro                   | -->
<!-- |    EDITING THIS FILE BY HAND IS NOT RECOMMENDED                                 | -->
<!-- =================================================================================== -->
<robot name="simple_robot">
  <!-- Links -->
  <link name="base_link"/>
  <link name="h_rod"/>
  <link name="cam_left">
    <visual>
      <geometry>
        <box size="0.05 0.05 0.05"/>
      </geometry>
      <material name="green">
        <color rgba="0 1 0 1"/>
      </material>
    </visual>
  </link>
  <link name="cam_right">
    <visual>
      <geometry>
        <box size="0.05 0.05 0.05"/>
      </geometry>
      <material name="blue">
        <color rgba="0 0 1 1"/>
      </material>
    </visual>
  </link>
  <!-- Joints -->
  <joint name="pitch_inclination" type="revolute">
    <parent link="base_link"/>
    <child link="h_rod"/>
    <origin rpy="0 0 0" xyz="0 0 0.16"/>
    <axis xyz="1 0 0"/>
    <limit effort="10" lower="-3.14" upper="3.14" velocity="1"/>
  </joint>
  <joint name="cam_left_yaw" type="revolute">
    <parent link="h_rod"/>
    <child link="cam_left"/>
    <origin rpy="0 0 0" xyz="-0.08125 0 0.04"/>
    <axis xyz="0 0 1"/>
    <limit effort="10" lower="-3.14" upper="3.14" velocity="1"/>
  </joint>
  <joint name="cam_right_yaw" type="revolute">
    <parent link="h_rod"/>
    <child link="cam_right"/>
    <origin rpy="0 0 0" xyz="0.08125 0 0.04"/>
    <axis xyz="0 0 1"/>
    <limit effort="10" lower="-3.14" upper="3.14" velocity="1"/>
  </joint>
</robot>
